Workbook

Sheet Sprint_1
A1: 📋 Sprint 1 — QA Workshop Release Planning
A3: 👤 Omar Kandeel
A4: Day | B4: Planned Hours | C4: Actual Hours | D4: Remaining Hours | E4: Status | F4: Task / Notes
A5: Day 1 | B5: 5 | C5: 5 | D5: =IF(AND(B5<>"",C5<>""),B5-C5,"") -> 0 | E5: ✅ Done
A6: Day 2 | B6: 0 | C6: 0 | D6: =IF(AND(B6<>"",C6<>""),B6-C6,"") -> 0 | E6: ✅ Done
A7: Day 3 | B7: 0 | C7: 0 | D7: 0 | E7: ✅ Done
A8: Day 4 | B8: 5 | C8: 3 | D8: =IF(AND(B8<>"",C8<>""),B8-C8,"") -> 2 | E8: ✅ Done
A9: Day 5 | B9: 2 | C9: 0 | D9: =IF(AND(B9<>"",C9<>""),B9-C9,"") -> 2 | E9: ✅ Done
A10: Day 6 | B10: 2 | C10: 5 | D10: =IF(AND(B10<>"",C10<>""),B10-C10,"") -> -3 | E10: ✅ Done
A11: Day 7 | B11: 0 | C11: 4 | D11: =IF(AND(B11<>"",C11<>""),B11-C11,"") -> -4 | E11: ✅ Done
A12: 📊 TOTAL | B12: =SUM(B5:B11) -> 14 | C12: =SUM(C5:C11) -> 17 | D12: =SUM(D5:D11) -> -3
A14: 👤 Abdelrahman Yasser
A15: Day | B15: Planned Hours | C15: Actual Hours | D15: Remaining Hours | E15: Status | F15: Task / Notes
A16: Day 1 | B16: 5 | C16: 5 | D16: =IF(AND(B16<>"",C16<>""),B16-C16,"") -> 0 | E16: ✅ Done
A17: Day 2 | B17: 0 | C17: 0 | D17: =IF(AND(B17<>"",C17<>""),B17-C17,"") -> 0 | E17: ✅ Done
A18: Day 3 | B18: 0 | C18: 0 | D18: 0 | E18: ✅ Done
A19: Day 4 | B19: 0 | C19: 0 | D19: =IF(AND(B19<>"",C19<>""),B19-C19,"") -> 0 | E19: ✅ Done
A20: Day 5 | B20: 3 | C20: 0 | D20: =IF(AND(B20<>"",C20<>""),B20-C20,"") -> 3 | E20: ⏳ Not Started
A21: Day 6 | B21: 3 | C21: 0 | D21: =IF(AND(B21<>"",C21<>""),B21-C21,"") -> 3 | E21: ⏳ Not Started
A22: Day 7 | B22: 1 | C22: 0 | D22: =IF(AND(B22<>"",C22<>""),B22-C22,"") -> 1 | E22: ⏳ Not Started
A23: 📊 TOTAL | B23: =SUM(B16:B22) -> 12 | C23: =SUM(C16:C22) -> 5 | D23: =SUM(D16:D22) -> 7
A25: 👤 Amr
A26: Day | B26: Planned Hours | C26: Actual Hours | D26: Remaining Hours | E26: Status | F26: Task / Notes
A27: Day 1 | B27: 5 | C27: 5 | D27: =IF(AND(B27<>"",C27<>""),B27-C27,"") -> 0 | E27: ✅ Done
A28: Day 2 | B28: 0 | C28: 0 | D28: =IF(AND(B28<>"",C28<>""),B28-C28,"") -> 0 | E28: ✅ Done
A29: Day 3 | B29: 0 | C29: 0 | D29: =IF(AND(B29<>"",C29<>""),B29-C29,"") -> 0 | E29: ✅ Done
A30: Day 4 | B30: 3 | C30: 3.5 | D30: =IF(AND(B30<>"",C30<>""),B30-C30,"") -> -0.5 | E30: 🔄 In Progress
A31: Day 5 | B31: 2 | C31: 1 | D31: =IF(AND(B31<>"",C31<>""),B31-C31,"") -> 1 | E31: ⏳ Not Started
A32: Day 6 | B32: 3 | C32: 4 | D32: =IF(AND(B32<>"",C32<>""),B32-C32,"") -> -1 | E32: ⏳ Not Started
A33: Day 7 | B33: 3 | C33: 5 | D33: =IF(AND(B33<>"",C33<>""),B33-C33,"") -> -2 | E33: ⏳ Not Started
A34: 📊 TOTAL | B34: =SUM(B27:B33) -> 16 | C34: =SUM(C27:C33) -> 18.5 | D34: =SUM(D27:D33) -> -2.5
A36: 👤 Amira
A37: Day | B37: Planned Hours | C37: Actual Hours | D37: Remaining Hours | E37: Status | F37: Task / Notes
A38: Day 1 | B38: 6 | C38: 6 | D38: =IF(AND(B38<>"",C38<>""),B38-C38,"") -> 0 | E38: ✅ Done
A39: Day 2 | B39: 0 | C39: 0 | D39: =IF(AND(B39<>"",C39<>""),B39-C39,"") -> 0 | E39: ✅ Done
A40: Day 3 | B40: 2 | C40: 0.5 | D40: =IF(AND(B40<>"",C40<>""),B40-C40,"") -> 1.5 | E40: ✅ Done
A41: Day 4 | B41: 2 | C41: 2 | D41: =IF(AND(B41<>"",C41<>""),B41-C41,"") -> 0 | E41: ✅ Done
A42: Day 5 | B42: 0 | C42: 0 | D42: =IF(AND(B42<>"",C42<>""),B42-C42,"") -> 0 | E42: ✅ Done
A43: Day 6 | B43: 3 | C43: 4 | D43: =IF(AND(B43<>"",C43<>""),B43-C43,"") -> -1 | E43: ✅ Done
A44: Day 7 | B44: 1 | C44: 2.5 | D44: =IF(AND(B44<>"",C44<>""),B44-C44,"") -> -1.5 | E44: ✅ Done
...

Sheet 📊 Dashboard
A1: 📊 QA Workshop — Release Planning Dashboard
A2: Team Hours Summary Across All Sprints
B4: Sprint 1 | D4: Sprint 2 | F4: Sprint 3 | H4: 📊 Totals
A5: Team Member | B5: Planned | C5: Actual | D5: Planned | E5: Actual | F5: Planned | G5: Actual | H5: Total Planned | I5: Total Actual | J5: Variance
A6: 👤 Omar Kandeel | B6: =Sprint_1!B12 -> 14 | C6: =Sprint_1!C12 -> 17 | D6: =Sprint_2!B12 -> 0 | E6: =Sprint_2!C12 -> 0 | F6: =Sprint_3!B12 -> 0 | G6: =Sprint_3!C12 -> 0 | H6: =B6+D6+F6 -> 14 | I6: =C6+E6+G6 -> 17 | J6: =H6-I6 -> -3
A7: 👤 Abdelrahman Yasser | B7: =Sprint_1!B23 -> 12 | C7: =Sprint_1!C23 -> 5 | D7: =Sprint_2!B23 -> 0 | E7: =Sprint_2!C23 -> 0 | F7: =Sprint_3!B23 -> 0 | G7: =Sprint_3!C23 -> 0 | H7: =B7+D7+F7 -> 12 | I7: =C7+E7+G7 -> 5 | J7: =H7-I7 -> 7
A8: 👤 Amr | B8: =Sprint_1!B34 -> 16 | C8: =Sprint_1!C34 -> 18.5 | D8: =Sprint_2!B34 -> 0 | E8: =Sprint_2!C34 -> 0 | F8: =Sprint_3!B34 -> 0 | G8: =Sprint_3!C34 -> 0 | H8: =B8+D8+F8 -> 16 | I8: =C8+E8+G8 -> 18.5 | J8: =H8-I8 -> -2.5
A9: 👤 Amira | B9: =Sprint_1!B45 -> 14 | C9: =Sprint_1!C45 -> 15 | D9: =Sprint_2!B45 -> 0 | E9: =Sprint_2!C45 -> 0 | F9: =Sprint_3!B45 -> 0 | G9: =Sprint_3!C45 -> 0 | H9: =B9+D9+F9 -> 14 | I9: =C9+E9+G9 -> 15 | J9: =H9-I9 -> -1
A10: 👤 Aya | B10: =Sprint_1!B56 -> 16 | C10: =Sprint_1!C56 -> 16.5 | D10: =Sprint_2!B56 -> 0 | E10: =Sprint_2!C56 -> 0 | F10: =Sprint_3!B56 -> 0 | G10: =Sprint_3!C56 -> 0 | H10: =B10+D10+F10 -> 16 | I10: =C10+E10+G10 -> 16.5 | J10: =H10-I10 -> -0.5
A11: 📊 GRAND TOTAL | B11: =SUM(B6:B10) -> 72 | C11: =SUM(C6:C10) -> 72 | D11: =SUM(D6:D10) -> 0 | E11: =SUM(E6:E10) -> 0 | F11: =SUM(F6:F10) -> 0 | G11: =SUM(G6:G10) -> 0 | H11: =SUM(H6:H10) -> 72 | I11: =SUM(I6:I10) -> 72 | J11: =SUM(J6:J10) -> 0

Sheet Sprint_2
A1: 📋 Sprint 2 — QA Workshop Release Planning
A3: 👤 Omar Kandeel
A4: Day | B4: Planned Hours | C4: Actual Hours | D4: Remaining Hours | E4: Status | F4: Task / Notes
A5: Day 1 | D5: =IF(AND(B5<>"",C5<>""),B5-C5,"")
A6: Day 2 | D6: =IF(AND(B6<>"",C6<>""),B6-C6,"")
A7: Day 3 | D7: =IF(AND(B7<>"",C7<>""),B7-C7,"")
A8: Day 4 | D8: =IF(AND(B8<>"",C8<>""),B8-C8,"")
A9: Day 5 | D9: =IF(AND(B9<>"",C9<>""),B9-C9,"")
A10: Day 6 | D10: =IF(AND(B10<>"",C10<>""),B10-C10,"")
A11: Day 7 | D11: =IF(AND(B11<>"",C11<>""),B11-C11,"")
A12: 📊 TOTAL | B12: =SUM(B5:B11) -> 0 | C12: =SUM(C5:C11) -> 0 | D12: =SUM(D5:D11) -> 0
A14: 👤 Abdelrahman Yasser
A15: Day | B15: Planned Hours | C15: Actual Hours | D15: Remaining Hours | E15: Status | F15: Task / Notes
A16: Day 1 | D16: =IF(AND(B16<>"",C16<>""),B16-C16,"")
A17: Day 2 | D17: =IF(AND(B17<>"",C17<>""),B17-C17,"")
A18: Day 3 | D18: =IF(AND(B18<>"",C18<>""),B18-C18,"")
A19: Day 4 | D19: =IF(AND(B19<>"",C19<>""),B19-C19,"")
A20: Day 5 | D20: =IF(AND(B20<>"",C20<>""),B20-C20,"")
A21: Day 6 | D21: =IF(AND(B21<>"",C21<>""),B21-C21,"")
A22: Day 7 | D22: =IF(AND(B22<>"",C22<>""),B22-C22,"")
A23: 📊 TOTAL | B23: =SUM(B16:B22) -> 0 | C23: =SUM(C16:C22) -> 0 | D23: =SUM(D16:D22) -> 0
A25: 👤 Amr
A26: Day | B26: Planned Hours | C26: Actual Hours | D26: Remaining Hours | E26: Status | F26: Task / Notes
A27: Day 1 | D27: =IF(AND(B27<>"",C27<>""),B27-C27,"")
A28: Day 2 | D28: =IF(AND(B28<>"",C28<>""),B28-C28,"")
A29: Day 3 | D29: =IF(AND(B29<>"",C29<>""),B29-C29,"")
A30: Day 4 | D30: =IF(AND(B30<>"",C30<>""),B30-C30,"")
A31: Day 5 | D31: =IF(AND(B31<>"",C31<>""),B31-C31,"")
A32: Day 6 | D32: =IF(AND(B32<>"",C32<>""),B32-C32,"")
A33: Day 7 | D33: =IF(AND(B33<>"",C33<>""),B33-C33,"")
A34: 📊 TOTAL | B34: =SUM(B27:B33) -> 0 | C34: =SUM(C27:C33) -> 0 | D34: =SUM(D27:D33) -> 0
A36: 👤 Amira
A37: Day | B37: Planned Hours | C37: Actual Hours | D37: Remaining Hours | E37: Status | F37: Task / Notes
A38: Day 1 | D38: =IF(AND(B38<>"",C38<>""),B38-C38,"")
A39: Day 2 | D39: =IF(AND(B39<>"",C39<>""),B39-C39,"")
A40: Day 3 | D40: =IF(AND(B40<>"",C40<>""),B40-C40,"")
A41: Day 4 | D41: =IF(AND(B41<>"",C41<>""),B41-C41,"")
A42: Day 5 | D42: =IF(AND(B42<>"",C42<>""),B42-C42,"")
A43: Day 6 | D43: =IF(AND(B43<>"",C43<>""),B43-C43,"")
A44: Day 7 | D44: =IF(AND(B44<>"",C44<>""),B44-C44,"")
...

Sheet Sprint_3
A1: 📋 Sprint 3 — QA Workshop Release Planning
A3: 👤 Omar Kandeel
A4: Day | B4: Planned Hours | C4: Actual Hours | D4: Remaining Hours | E4: Status | F4: Task / Notes
A5: Day 1 | D5: =IF(AND(B5<>"",C5<>""),B5-C5,"")
A6: Day 2 | D6: =IF(AND(B6<>"",C6<>""),B6-C6,"")
A7: Day 3 | D7: =IF(AND(B7<>"",C7<>""),B7-C7,"")
A8: Day 4 | D8: =IF(AND(B8<>"",C8<>""),B8-C8,"")
A9: Day 5 | D9: =IF(AND(B9<>"",C9<>""),B9-C9,"")
A10: Day 6 | D10: =IF(AND(B10<>"",C10<>""),B10-C10,"")
A11: Day 7 | D11: =IF(AND(B11<>"",C11<>""),B11-C11,"")
A12: 📊 TOTAL | B12: =SUM(B5:B11) -> 0 | C12: =SUM(C5:C11) -> 0 | D12: =SUM(D5:D11) -> 0
A14: 👤 Abdelrahman Yasser
A15: Day | B15: Planned Hours | C15: Actual Hours | D15: Remaining Hours | E15: Status | F15: Task / Notes
A16: Day 1 | D16: =IF(AND(B16<>"",C16<>""),B16-C16,"")
A17: Day 2 | D17: =IF(AND(B17<>"",C17<>""),B17-C17,"")
A18: Day 3 | D18: =IF(AND(B18<>"",C18<>""),B18-C18,"")
A19: Day 4 | D19: =IF(AND(B19<>"",C19<>""),B19-C19,"")
A20: Day 5 | D20: =IF(AND(B20<>"",C20<>""),B20-C20,"")
A21: Day 6 | D21: =IF(AND(B21<>"",C21<>""),B21-C21,"")
A22: Day 7 | D22: =IF(AND(B22<>"",C22<>""),B22-C22,"")
A23: 📊 TOTAL | B23: =SUM(B16:B22) -> 0 | C23: =SUM(C16:C22) -> 0 | D23: =SUM(D16:D22) -> 0
A25: 👤 Amr
A26: Day | B26: Planned Hours | C26: Actual Hours | D26: Remaining Hours | E26: Status | F26: Task / Notes
A27: Day 1 | D27: =IF(AND(B27<>"",C27<>""),B27-C27,"")
A28: Day 2 | D28: =IF(AND(B28<>"",C28<>""),B28-C28,"")
A29: Day 3 | D29: =IF(AND(B29<>"",C29<>""),B29-C29,"")
A30: Day 4 | D30: =IF(AND(B30<>"",C30<>""),B30-C30,"")
A31: Day 5 | D31: =IF(AND(B31<>"",C31<>""),B31-C31,"")
A32: Day 6 | D32: =IF(AND(B32<>"",C32<>""),B32-C32,"")
A33: Day 7 | D33: =IF(AND(B33<>"",C33<>""),B33-C33,"")
A34: 📊 TOTAL | B34: =SUM(B27:B33) -> 0 | C34: =SUM(C27:C33) -> 0 | D34: =SUM(D27:D33) -> 0
A36: 👤 Amira
A37: Day | B37: Planned Hours | C37: Actual Hours | D37: Remaining Hours | E37: Status | F37: Task / Notes
A38: Day 1 | D38: =IF(AND(B38<>"",C38<>""),B38-C38,"")
A39: Day 2 | D39: =IF(AND(B39<>"",C39<>""),B39-C39,"")
A40: Day 3 | D40: =IF(AND(B40<>"",C40<>""),B40-C40,"")
A41: Day 4 | D41: =IF(AND(B41<>"",C41<>""),B41-C41,"")
A42: Day 5 | D42: =IF(AND(B42<>"",C42<>""),B42-C42,"")
A43: Day 6 | D43: =IF(AND(B43<>"",C43<>""),B43-C43,"")
A44: Day 7 | D44: =IF(AND(B44<>"",C44<>""),B44-C44,"")
...
